[2017-02-26 00:42:22 +0000] [37263] [INFO] Starting gunicorn 19.6.0
[2017-02-26 00:42:22 +0000] [37263] [INFO] Listening at: http://127.0.0.1:8000 (37263)
[2017-02-26 00:42:22 +0000] [37263] [INFO] Using worker: sync
[2017-02-26 00:42:22 +0000] [37267] [INFO] Booting worker with pid: 37267
W tensorflow/core/platform/cpu_feature_guard.cc:45] The TensorFlow library wasn't compiled to use SSE3 instructions, but these are available on your machine and could speed up CPU computations.
W tensorflow/core/platform/cpu_feature_guard.cc:45] The TensorFlow library wasn't compiled to use SSE4.1 instructions, but these are available on your machine and could speed up CPU computations.
W tensorflow/core/platform/cpu_feature_guard.cc:45] The TensorFlow library wasn't compiled to use SSE4.2 instructions, but these are available on your machine and could speed up CPU computations.
W tensorflow/core/platform/cpu_feature_guard.cc:45] The TensorFlow library wasn't compiled to use AVX instructions, but these are available on your machine and could speed up CPU computations.
W tensorflow/core/platform/cpu_feature_guard.cc:45] The TensorFlow library wasn't compiled to use AVX2 instructions, but these are available on your machine and could speed up CPU computations.
W tensorflow/core/platform/cpu_feature_guard.cc:45] The TensorFlow library wasn't compiled to use FMA instructions, but these are available on your machine and could speed up CPU computations.
[2017-02-26 00:42:54,535] ERROR in app: Exception on /api [POST]
Traceback (most recent call last):
  File "/usr/local/lib/python3.5/dist-packages/flask/app.py", line 1982, in wsgi_app
    response = self.full_dispatch_request()
  File "/usr/local/lib/python3.5/dist-packages/flask/app.py", line 1614, in full_dispatch_request
    rv = self.handle_user_exception(e)
  File "/usr/local/lib/python3.5/dist-packages/flask/app.py", line 1517, in handle_user_exception
    reraise(exc_type, exc_value, tb)
  File "/usr/local/lib/python3.5/dist-packages/flask/_compat.py", line 33, in reraise
    raise value
  File "/usr/local/lib/python3.5/dist-packages/flask/app.py", line 1612, in full_dispatch_request
    rv = self.dispatch_request()
  File "/usr/local/lib/python3.5/dist-packages/flask/app.py", line 1598, in dispatch_request
    return self.view_functions[rule.endpoint](**req.view_args)
  File "/home/alaktionov/nm_send_nudes/send_nudes/web_app/app.py", line 32, in names
    res = porn_creator.process_image(image)
  File "/home/alaktionov/nm_send_nudes/send_nudes/face_to_vec/porn_creator.py", line 196, in process_image
    return get_porn(api.find_closest(im), im)
  File "/home/alaktionov/nm_send_nudes/send_nudes/face_to_vec/porn_creator.py", line 169, in get_porn
    landmarks1 = read_im_and_landmarks(im1)
  File "/home/alaktionov/nm_send_nudes/send_nudes/face_to_vec/porn_creator.py", line 124, in read_im_and_landmarks
    s = get_landmarks(im)
  File "/home/alaktionov/nm_send_nudes/send_nudes/face_to_vec/porn_creator.py", line 56, in get_landmarks
    rects = detector(im, 1)
RuntimeError: Unsupported image type, must be 8bit gray or RGB image.
[2017-02-26 00:43:34 +0000] [37263] [INFO] Handling signal: int
[2017-02-26 00:43:35 +0000] [37267] [INFO] Worker exiting (pid: 37267)
[DEEPGAZE] head_pose_estimation.py: the dlib library is installed.

[[  1.97442752   0.        ]
 [  0.           0.        ]
 [ -4.17962217   0.        ]
 [ 13.7389822    0.        ]
 [  0.          -1.        ]
 [  0.          -1.        ]
 [  0.           0.        ]
 [  0.           0.        ]
 [  0.           0.        ]
 [  0.           0.        ]
 [  0.           0.        ]
 [  0.           0.        ]
 [ -1.           0.        ]
 [  0.           0.        ]
 [  0.           0.        ]
 [  0.           0.        ]
 [  0.           0.        ]
 [  0.           0.        ]
 [  0.           0.        ]
 [  0.           0.        ]
 [  0.           0.        ]
 [  0.           0.        ]
 [  0.           0.        ]
 [  0.           0.        ]
 [  0.           0.        ]
 [  0.           0.        ]
 [  0.           0.        ]
 [  0.           0.        ]
 [  0.           0.        ]
 [  0.           0.        ]
 [  0.           0.        ]
 [  0.           0.        ]
 [  0.           0.        ]
 [  0.           0.        ]
 [  0.           0.        ]
 [  0.           0.        ]
 [  0.           0.        ]
 [  0.           0.        ]
 [  0.           0.        ]
 [  0.           0.        ]
 [  0.           0.        ]
 [  0.           0.        ]
 [  0.           0.        ]
 [  0.           0.        ]
 [  0.           0.        ]
 [  0.           0.        ]
 [  0.           0.        ]
 [  0.           0.        ]
 [  0.           0.        ]
 [  0.           0.        ]
 [  0.           0.        ]
 [  0.           0.        ]
 [  0.           0.        ]
 [  0.           0.        ]
 [  0.           0.        ]
 [  0.           0.        ]
 [  0.           0.        ]
 [  0.           0.        ]
 [  0.           0.        ]
 [  0.           0.        ]
 [  0.           0.        ]
 [  0.           0.        ]
 [  0.           0.        ]
 [  0.           0.        ]
 [  0.           0.        ]
 [  0.           0.        ]
 [  0.           0.        ]
 [  0.           0.        ]
 [  0.           0.        ]
 [  0.           0.        ]
 [  0.           0.        ]
 [  0.           0.        ]]
None
-1.0
Exception ignored in: <bound method BaseSession.__del__ of <tensorflow.python.client.session.Session object at 0x7ffa5d1eda58>>
Traceback (most recent call last):
  File "/home/alaktionov/.local/lib/python3.5/site-packages/tensorflow/python/client/session.py", line 582, in __del__
AttributeError: 'NoneType' object has no attribute 'TF_DeleteStatus'
[2017-02-26 00:43:35 +0000] [37263] [INFO] Shutting down: Master
